2025-08-18 08:27:50 WARNING: PyNaCl is not installed, voice will NOT be supported
2025-08-18 08:28:15 WARNING: PyNaCl is not installed, voice will NOT be supported
2025-08-18 08:28:15 WARNING: Privileged message content intent is missing, commands may not work as expected.
2025-08-18 08:28:15 INFO: logging in using static token
2025-08-18 08:29:39 WARNING: PyNaCl is not installed, voice will NOT be supported
2025-08-18 08:31:23 WARNING: PyNaCl is not installed, voice will NOT be supported
2025-08-18 08:31:23 WARNING: Privileged message content intent is missing, commands may not work as expected.
2025-08-18 08:31:23 INFO: logging in using static token
2025-08-18 08:31:24 INFO: Shard ID None has connected to Gateway (Session ID: b4cc1ef8a10ba7976d1709b9c2653547).
2025-08-18 08:31:26 INFO: Bot ready: StreamerSpy#4390
2025-08-18 08:31:26 ERROR: Ignoring exception in on_ready
Traceback (most recent call last):
  File "C:\Users\adlerluc\Pictures\workspace2\.venv\Lib\site-packages\discord\client.py", line 481, in _run_event
    await coro(*args, **kwargs)
  File "C:\Users\adlerluc\Pictures\workspace2\Bot.py", line 322, in on_ready
    await bot.tree.sync()
  File "C:\Users\adlerluc\Pictures\workspace2\.venv\Lib\site-packages\discord\app_commands\tree.py", line 1134, in sync
    raise CommandSyncFailure(e, commands) from None
discord.app_commands.errors.CommandSyncFailure: Failed to upload commands to Discord (HTTP status 400, error code 50035)
In group 'streamspy' defined in module '__main__'
  In command 'streamspy addstreamer' defined in function 'add_streamer'
    description: Must be between 1 and 100 in length.
2025-08-18 08:32:43 ERROR: Unclosed client session
client_session: <aiohttp.client.ClientSession object at 0x000001C60A855250>
2025-08-18 08:32:44 WARNING: PyNaCl is not installed, voice will NOT be supported
2025-08-18 08:32:44 WARNING: Privileged message content intent is missing, commands may not work as expected.
2025-08-18 08:32:44 INFO: logging in using static token
2025-08-18 08:32:45 INFO: Shard ID None has connected to Gateway (Session ID: 92c3809bc9102d0e98b6ce90bfdc60a1).
2025-08-18 08:32:47 INFO: Bot ready: StreamerSpy#4390
2025-08-18 08:35:29 INFO: Saved streamspy state: 1 guilds
2025-08-18 08:35:48 ERROR: Fehler beim Prüfen von shurjoka in Guild 1405456407867822182: Cannot connect to host id.twitch.tv:443 ssl:default [Der angegebene Netzwerkname ist nicht mehr verfügbar]
Traceback (most recent call last):
  File "C:\Users\adlerluc\AppData\Local\Programs\Python\Python312\Lib\asyncio\windows_events.py", line 462, in finish_socket_func
    return ov.getresult()
           ^^^^^^^^^^^^^^
OSError: [WinError 64] Der angegebene Netzwerkname ist nicht mehr verfügbar

During handling of the above exception, another exception occurred:

Traceback (most recent call last):
  File "C:\Users\adlerluc\Pictures\workspace2\.venv\Lib\site-packages\aiohttp\connector.py", line 1283, in _wrap_create_connection
    return await self._loop.create_connection(*args, **kwargs, sock=sock)
           ^^^^^^^^^^^^^^^^^^^^^^^^^^^^^^^^^^^^^^^^^^^^^^^^^^^^^^^^^^^^^^
  File "C:\Users\adlerluc\AppData\Local\Programs\Python\Python312\Lib\asyncio\base_events.py", line 1149, in create_connection
    transport, protocol = await self._create_connection_transport(
                          ^^^^^^^^^^^^^^^^^^^^^^^^^^^^^^^^^^^^^^^^
  File "C:\Users\adlerluc\AppData\Local\Programs\Python\Python312\Lib\asyncio\base_events.py", line 1182, in _create_connection_transport
    await waiter
  File "C:\Users\adlerluc\AppData\Local\Programs\Python\Python312\Lib\asyncio\proactor_events.py", line 286, in _loop_reading
    length = fut.result()
             ^^^^^^^^^^^^
  File "C:\Users\adlerluc\AppData\Local\Programs\Python\Python312\Lib\asyncio\windows_events.py", line 803, in _poll
    value = callback(transferred, key, ov)
            ^^^^^^^^^^^^^^^^^^^^^^^^^^^^^^
  File "C:\Users\adlerluc\AppData\Local\Programs\Python\Python312\Lib\asyncio\windows_events.py", line 466, in finish_socket_func
    raise ConnectionResetError(*exc.args)
ConnectionResetError: [WinError 64] Der angegebene Netzwerkname ist nicht mehr verfügbar

The above exception was the direct cause of the following exception:

Traceback (most recent call last):
  File "C:\Users\adlerluc\Pictures\workspace2\Bot.py", line 197, in check_stream
    data = await twitch.get_stream(session, streamer)
           ^^^^^^^^^^^^^^^^^^^^^^^^^^^^^^^^^^^^^^^^^^
  File "C:\Users\adlerluc\Pictures\workspace2\Bot.py", line 141, in get_stream
    await self.ensure_token(session)
  File "C:\Users\adlerluc\Pictures\workspace2\Bot.py", line 131, in ensure_token
    async with session.post(url, params=params) as resp:
  File "C:\Users\adlerluc\Pictures\workspace2\.venv\Lib\site-packages\aiohttp\client.py", line 1488, in __aenter__
    self._resp: _RetType = await self._coro
                           ^^^^^^^^^^^^^^^^
  File "C:\Users\adlerluc\Pictures\workspace2\.venv\Lib\site-packages\aiohttp\client.py", line 770, in _request
    resp = await handler(req)
           ^^^^^^^^^^^^^^^^^^
  File "C:\Users\adlerluc\Pictures\workspace2\.venv\Lib\site-packages\aiohttp\client.py", line 725, in _connect_and_send_request
    conn = await self._connector.connect(
           ^^^^^^^^^^^^^^^^^^^^^^^^^^^^^^
  File "C:\Users\adlerluc\Pictures\workspace2\.venv\Lib\site-packages\aiohttp\connector.py", line 642, in connect
    proto = await self._create_connection(req, traces, timeout)
            ^^^^^^^^^^^^^^^^^^^^^^^^^^^^^^^^^^^^^^^^^^^^^^^^^^^
  File "C:\Users\adlerluc\Pictures\workspace2\.venv\Lib\site-packages\aiohttp\connector.py", line 1209, in _create_connection
    _, proto = await self._create_direct_connection(req, traces, timeout)
               ^^^^^^^^^^^^^^^^^^^^^^^^^^^^^^^^^^^^^^^^^^^^^^^^^^^^^^^^^^
  File "C:\Users\adlerluc\Pictures\workspace2\.venv\Lib\site-packages\aiohttp\connector.py", line 1581, in _create_direct_connection
    raise last_exc
  File "C:\Users\adlerluc\Pictures\workspace2\.venv\Lib\site-packages\aiohttp\connector.py", line 1550, in _create_direct_connection
    transp, proto = await self._wrap_create_connection(
                    ^^^^^^^^^^^^^^^^^^^^^^^^^^^^^^^^^^^
  File "C:\Users\adlerluc\Pictures\workspace2\.venv\Lib\site-packages\aiohttp\connector.py", line 1291, in _wrap_create_connection
    raise client_error(req.connection_key, exc) from exc
aiohttp.client_exceptions.ClientConnectorError: Cannot connect to host id.twitch.tv:443 ssl:default [Der angegebene Netzwerkname ist nicht mehr verfügbar]
2025-08-18 08:36:48 ERROR: Fehler beim Prüfen von shurjoka in Guild 1405456407867822182: Cannot connect to host id.twitch.tv:443 ssl:default [Der angegebene Netzwerkname ist nicht mehr verfügbar]
Traceback (most recent call last):
  File "C:\Users\adlerluc\AppData\Local\Programs\Python\Python312\Lib\asyncio\windows_events.py", line 462, in finish_socket_func
    return ov.getresult()
           ^^^^^^^^^^^^^^
OSError: [WinError 64] Der angegebene Netzwerkname ist nicht mehr verfügbar

During handling of the above exception, another exception occurred:

Traceback (most recent call last):
  File "C:\Users\adlerluc\Pictures\workspace2\.venv\Lib\site-packages\aiohttp\connector.py", line 1283, in _wrap_create_connection
    return await self._loop.create_connection(*args, **kwargs, sock=sock)
           ^^^^^^^^^^^^^^^^^^^^^^^^^^^^^^^^^^^^^^^^^^^^^^^^^^^^^^^^^^^^^^
  File "C:\Users\adlerluc\AppData\Local\Programs\Python\Python312\Lib\asyncio\base_events.py", line 1149, in create_connection
    transport, protocol = await self._create_connection_transport(
                          ^^^^^^^^^^^^^^^^^^^^^^^^^^^^^^^^^^^^^^^^
  File "C:\Users\adlerluc\AppData\Local\Programs\Python\Python312\Lib\asyncio\base_events.py", line 1182, in _create_connection_transport
    await waiter
  File "C:\Users\adlerluc\AppData\Local\Programs\Python\Python312\Lib\asyncio\proactor_events.py", line 286, in _loop_reading
    length = fut.result()
             ^^^^^^^^^^^^
  File "C:\Users\adlerluc\AppData\Local\Programs\Python\Python312\Lib\asyncio\windows_events.py", line 803, in _poll
    value = callback(transferred, key, ov)
            ^^^^^^^^^^^^^^^^^^^^^^^^^^^^^^
  File "C:\Users\adlerluc\AppData\Local\Programs\Python\Python312\Lib\asyncio\windows_events.py", line 466, in finish_socket_func
    raise ConnectionResetError(*exc.args)
ConnectionResetError: [WinError 64] Der angegebene Netzwerkname ist nicht mehr verfügbar

The above exception was the direct cause of the following exception:

Traceback (most recent call last):
  File "C:\Users\adlerluc\Pictures\workspace2\Bot.py", line 197, in check_stream
    for guild in bot.guilds:
                       ^^^^^^
  File "C:\Users\adlerluc\Pictures\workspace2\Bot.py", line 141, in get_stream
    expires_in = data.get("expires_in", 3600)
    ^^^^^^^^^^^^^^^^^^^^^^^^^^^^^^^^
  File "C:\Users\adlerluc\Pictures\workspace2\Bot.py", line 131, in ensure_token
    # Retry on transient network errors
  File "C:\Users\adlerluc\Pictures\workspace2\.venv\Lib\site-packages\aiohttp\client.py", line 1488, in __aenter__
    self._resp: _RetType = await self._coro
                           ^^^^^^^^^^^^^^^^
  File "C:\Users\adlerluc\Pictures\workspace2\.venv\Lib\site-packages\aiohttp\client.py", line 770, in _request
    resp = await handler(req)
           ^^^^^^^^^^^^^^^^^^
  File "C:\Users\adlerluc\Pictures\workspace2\.venv\Lib\site-packages\aiohttp\client.py", line 725, in _connect_and_send_request
    conn = await self._connector.connect(
           ^^^^^^^^^^^^^^^^^^^^^^^^^^^^^^
  File "C:\Users\adlerluc\Pictures\workspace2\.venv\Lib\site-packages\aiohttp\connector.py", line 642, in connect
    proto = await self._create_connection(req, traces, timeout)
            ^^^^^^^^^^^^^^^^^^^^^^^^^^^^^^^^^^^^^^^^^^^^^^^^^^^
  File "C:\Users\adlerluc\Pictures\workspace2\.venv\Lib\site-packages\aiohttp\connector.py", line 1209, in _create_connection
    _, proto = await self._create_direct_connection(req, traces, timeout)
               ^^^^^^^^^^^^^^^^^^^^^^^^^^^^^^^^^^^^^^^^^^^^^^^^^^^^^^^^^^
  File "C:\Users\adlerluc\Pictures\workspace2\.venv\Lib\site-packages\aiohttp\connector.py", line 1581, in _create_direct_connection
    raise last_exc
  File "C:\Users\adlerluc\Pictures\workspace2\.venv\Lib\site-packages\aiohttp\connector.py", line 1550, in _create_direct_connection
    transp, proto = await self._wrap_create_connection(
                    ^^^^^^^^^^^^^^^^^^^^^^^^^^^^^^^^^^^
  File "C:\Users\adlerluc\Pictures\workspace2\.venv\Lib\site-packages\aiohttp\connector.py", line 1291, in _wrap_create_connection
    raise client_error(req.connection_key, exc) from exc
aiohttp.client_exceptions.ClientConnectorError: Cannot connect to host id.twitch.tv:443 ssl:default [Der angegebene Netzwerkname ist nicht mehr verfügbar]
2025-08-18 08:36:57 ERROR: Unclosed client session
client_session: <aiohttp.client.ClientSession object at 0x000001829C581010>
2025-08-18 08:37:20 WARNING: PyNaCl is not installed, voice will NOT be supported
2025-08-18 08:37:20 WARNING: Privileged message content intent is missing, commands may not work as expected.
2025-08-18 08:37:20 INFO: logging in using static token
2025-08-18 08:37:21 INFO: Shard ID None has connected to Gateway (Session ID: 64d19fa464d6393669104c5f75e43a00).
2025-08-18 08:37:23 INFO: Bot ready: StreamerSpy#4390
2025-08-18 08:38:15 ERROR: Unclosed client session
client_session: <aiohttp.client.ClientSession object at 0x000002AB6CFA22D0>
2025-08-18 08:38:31 WARNING: PyNaCl is not installed, voice will NOT be supported
2025-08-18 08:38:31 WARNING: Privileged message content intent is missing, commands may not work as expected.
2025-08-18 08:38:31 INFO: logging in using static token
2025-08-18 08:38:32 INFO: Shard ID None has connected to Gateway (Session ID: bf9a138ab2863a78c13542281bbc513b).
2025-08-18 08:38:34 INFO: Bot ready: StreamerSpy#4390
2025-08-18 08:38:34 INFO: Loaded streamspy state: 1 guilds
2025-08-18 08:38:34 WARNING: Attempt 1/3: network error while fetching Twitch token: Cannot connect to host id.twitch.tv:443 ssl:default [Der angegebene Netzwerkname ist nicht mehr verfügbar]
2025-08-18 08:38:36 WARNING: Attempt 2/3: network error while fetching Twitch token: Cannot connect to host id.twitch.tv:443 ssl:default [Der angegebene Netzwerkname ist nicht mehr verfügbar]
2025-08-18 08:38:40 WARNING: Attempt 3/3: network error while fetching Twitch token: Cannot connect to host id.twitch.tv:443 ssl:default [Der angegebene Netzwerkname ist nicht mehr verfügbar]
2025-08-18 08:38:40 ERROR: Exceeded attempts fetching Twitch token
Traceback (most recent call last):
  File "C:\Users\adlerluc\AppData\Local\Programs\Python\Python312\Lib\asyncio\windows_events.py", line 462, in finish_socket_func
    return ov.getresult()
           ^^^^^^^^^^^^^^
OSError: [WinError 64] Der angegebene Netzwerkname ist nicht mehr verfügbar

During handling of the above exception, another exception occurred:

Traceback (most recent call last):
  File "C:\Users\adlerluc\Pictures\workspace2\.venv\Lib\site-packages\aiohttp\connector.py", line 1283, in _wrap_create_connection
    return await self._loop.create_connection(*args, **kwargs, sock=sock)
           ^^^^^^^^^^^^^^^^^^^^^^^^^^^^^^^^^^^^^^^^^^^^^^^^^^^^^^^^^^^^^^
  File "C:\Users\adlerluc\AppData\Local\Programs\Python\Python312\Lib\asyncio\base_events.py", line 1149, in create_connection
    transport, protocol = await self._create_connection_transport(
                          ^^^^^^^^^^^^^^^^^^^^^^^^^^^^^^^^^^^^^^^^
  File "C:\Users\adlerluc\AppData\Local\Programs\Python\Python312\Lib\asyncio\base_events.py", line 1182, in _create_connection_transport
    await waiter
  File "C:\Users\adlerluc\AppData\Local\Programs\Python\Python312\Lib\asyncio\proactor_events.py", line 286, in _loop_reading
    length = fut.result()
             ^^^^^^^^^^^^
  File "C:\Users\adlerluc\AppData\Local\Programs\Python\Python312\Lib\asyncio\windows_events.py", line 803, in _poll
    value = callback(transferred, key, ov)
            ^^^^^^^^^^^^^^^^^^^^^^^^^^^^^^
  File "C:\Users\adlerluc\AppData\Local\Programs\Python\Python312\Lib\asyncio\windows_events.py", line 466, in finish_socket_func
    raise ConnectionResetError(*exc.args)
ConnectionResetError: [WinError 64] Der angegebene Netzwerkname ist nicht mehr verfügbar

The above exception was the direct cause of the following exception:

Traceback (most recent call last):
  File "C:\Users\adlerluc\Pictures\workspace2\Bot.py", line 135, in ensure_token
    async with session.post(url, params=params) as resp:
  File "C:\Users\adlerluc\Pictures\workspace2\.venv\Lib\site-packages\aiohttp\client.py", line 1488, in __aenter__
    self._resp: _RetType = await self._coro
                           ^^^^^^^^^^^^^^^^
  File "C:\Users\adlerluc\Pictures\workspace2\.venv\Lib\site-packages\aiohttp\client.py", line 770, in _request
    resp = await handler(req)
           ^^^^^^^^^^^^^^^^^^
  File "C:\Users\adlerluc\Pictures\workspace2\.venv\Lib\site-packages\aiohttp\client.py", line 725, in _connect_and_send_request
    conn = await self._connector.connect(
           ^^^^^^^^^^^^^^^^^^^^^^^^^^^^^^
  File "C:\Users\adlerluc\Pictures\workspace2\.venv\Lib\site-packages\aiohttp\connector.py", line 642, in connect
    proto = await self._create_connection(req, traces, timeout)
            ^^^^^^^^^^^^^^^^^^^^^^^^^^^^^^^^^^^^^^^^^^^^^^^^^^^
  File "C:\Users\adlerluc\Pictures\workspace2\.venv\Lib\site-packages\aiohttp\connector.py", line 1209, in _create_connection
    _, proto = await self._create_direct_connection(req, traces, timeout)
               ^^^^^^^^^^^^^^^^^^^^^^^^^^^^^^^^^^^^^^^^^^^^^^^^^^^^^^^^^^
  File "C:\Users\adlerluc\Pictures\workspace2\.venv\Lib\site-packages\aiohttp\connector.py", line 1581, in _create_direct_connection
    raise last_exc
  File "C:\Users\adlerluc\Pictures\workspace2\.venv\Lib\site-packages\aiohttp\connector.py", line 1550, in _create_direct_connection
    transp, proto = await self._wrap_create_connection(
                    ^^^^^^^^^^^^^^^^^^^^^^^^^^^^^^^^^^^
  File "C:\Users\adlerluc\Pictures\workspace2\.venv\Lib\site-packages\aiohttp\connector.py", line 1291, in _wrap_create_connection
    raise client_error(req.connection_key, exc) from exc
aiohttp.client_exceptions.ClientConnectorError: Cannot connect to host id.twitch.tv:443 ssl:default [Der angegebene Netzwerkname ist nicht mehr verfügbar]
2025-08-18 08:38:40 ERROR: Fehler beim Prüfen von shurjoka in Guild 1405456407867822182: Cannot connect to host id.twitch.tv:443 ssl:default [Der angegebene Netzwerkname ist nicht mehr verfügbar]
Traceback (most recent call last):
  File "C:\Users\adlerluc\AppData\Local\Programs\Python\Python312\Lib\asyncio\windows_events.py", line 462, in finish_socket_func
    return ov.getresult()
           ^^^^^^^^^^^^^^
OSError: [WinError 64] Der angegebene Netzwerkname ist nicht mehr verfügbar

During handling of the above exception, another exception occurred:

Traceback (most recent call last):
  File "C:\Users\adlerluc\Pictures\workspace2\.venv\Lib\site-packages\aiohttp\connector.py", line 1283, in _wrap_create_connection
    return await self._loop.create_connection(*args, **kwargs, sock=sock)
           ^^^^^^^^^^^^^^^^^^^^^^^^^^^^^^^^^^^^^^^^^^^^^^^^^^^^^^^^^^^^^^
  File "C:\Users\adlerluc\AppData\Local\Programs\Python\Python312\Lib\asyncio\base_events.py", line 1149, in create_connection
    transport, protocol = await self._create_connection_transport(
                          ^^^^^^^^^^^^^^^^^^^^^^^^^^^^^^^^^^^^^^^^
  File "C:\Users\adlerluc\AppData\Local\Programs\Python\Python312\Lib\asyncio\base_events.py", line 1182, in _create_connection_transport
    await waiter
  File "C:\Users\adlerluc\AppData\Local\Programs\Python\Python312\Lib\asyncio\proactor_events.py", line 286, in _loop_reading
    length = fut.result()
             ^^^^^^^^^^^^
  File "C:\Users\adlerluc\AppData\Local\Programs\Python\Python312\Lib\asyncio\windows_events.py", line 803, in _poll
    value = callback(transferred, key, ov)
            ^^^^^^^^^^^^^^^^^^^^^^^^^^^^^^
  File "C:\Users\adlerluc\AppData\Local\Programs\Python\Python312\Lib\asyncio\windows_events.py", line 466, in finish_socket_func
    raise ConnectionResetError(*exc.args)
ConnectionResetError: [WinError 64] Der angegebene Netzwerkname ist nicht mehr verfügbar

The above exception was the direct cause of the following exception:

Traceback (most recent call last):
  File "C:\Users\adlerluc\Pictures\workspace2\Bot.py", line 214, in check_stream
    data = await twitch.get_stream(session, streamer)
           ^^^^^^^^^^^^^^^^^^^^^^^^^^^^^^^^^^^^^^^^^^
  File "C:\Users\adlerluc\Pictures\workspace2\Bot.py", line 153, in get_stream
    await self.ensure_token(session)
  File "C:\Users\adlerluc\Pictures\workspace2\Bot.py", line 135, in ensure_token
    async with session.post(url, params=params) as resp:
  File "C:\Users\adlerluc\Pictures\workspace2\.venv\Lib\site-packages\aiohttp\client.py", line 1488, in __aenter__
    self._resp: _RetType = await self._coro
                           ^^^^^^^^^^^^^^^^
  File "C:\Users\adlerluc\Pictures\workspace2\.venv\Lib\site-packages\aiohttp\client.py", line 770, in _request
    resp = await handler(req)
           ^^^^^^^^^^^^^^^^^^
  File "C:\Users\adlerluc\Pictures\workspace2\.venv\Lib\site-packages\aiohttp\client.py", line 725, in _connect_and_send_request
    conn = await self._connector.connect(
           ^^^^^^^^^^^^^^^^^^^^^^^^^^^^^^
  File "C:\Users\adlerluc\Pictures\workspace2\.venv\Lib\site-packages\aiohttp\connector.py", line 642, in connect
    proto = await self._create_connection(req, traces, timeout)
            ^^^^^^^^^^^^^^^^^^^^^^^^^^^^^^^^^^^^^^^^^^^^^^^^^^^
  File "C:\Users\adlerluc\Pictures\workspace2\.venv\Lib\site-packages\aiohttp\connector.py", line 1209, in _create_connection
    _, proto = await self._create_direct_connection(req, traces, timeout)
               ^^^^^^^^^^^^^^^^^^^^^^^^^^^^^^^^^^^^^^^^^^^^^^^^^^^^^^^^^^
  File "C:\Users\adlerluc\Pictures\workspace2\.venv\Lib\site-packages\aiohttp\connector.py", line 1581, in _create_direct_connection
    raise last_exc
  File "C:\Users\adlerluc\Pictures\workspace2\.venv\Lib\site-packages\aiohttp\connector.py", line 1550, in _create_direct_connection
    transp, proto = await self._wrap_create_connection(
                    ^^^^^^^^^^^^^^^^^^^^^^^^^^^^^^^^^^^
  File "C:\Users\adlerluc\Pictures\workspace2\.venv\Lib\site-packages\aiohttp\connector.py", line 1291, in _wrap_create_connection
    raise client_error(req.connection_key, exc) from exc
aiohttp.client_exceptions.ClientConnectorError: Cannot connect to host id.twitch.tv:443 ssl:default [Der angegebene Netzwerkname ist nicht mehr verfügbar]
2025-08-18 08:38:57 ERROR: Unclosed client session
client_session: <aiohttp.client.ClientSession object at 0x000001E0EBB2BFB0>
2025-08-18 08:39:29 WARNING: PyNaCl is not installed, voice will NOT be supported
2025-08-18 08:39:29 WARNING: Privileged message content intent is missing, commands may not work as expected.
2025-08-18 08:39:29 INFO: logging in using static token
2025-08-18 08:39:30 INFO: Shard ID None has connected to Gateway (Session ID: 2cba5cad7937286e99a1feda2737c582).
2025-08-18 08:39:32 INFO: Bot ready: StreamerSpy#4390
2025-08-18 08:39:32 INFO: Loaded streamspy state: 1 guilds
2025-08-18 08:39:32 WARNING: Attempt 1/3: network error while fetching Twitch token: Cannot connect to host id.twitch.tv:443 ssl:default [Der angegebene Netzwerkname ist nicht mehr verfügbar]
2025-08-18 08:39:34 WARNING: Attempt 2/3: network error while fetching Twitch token: Cannot connect to host id.twitch.tv:443 ssl:default [Der angegebene Netzwerkname ist nicht mehr verfügbar]
2025-08-18 08:39:38 WARNING: Attempt 3/3: network error while fetching Twitch token: Cannot connect to host id.twitch.tv:443 ssl:default [Der angegebene Netzwerkname ist nicht mehr verfügbar]
2025-08-18 08:39:38 ERROR: Exceeded attempts fetching Twitch token
Traceback (most recent call last):
  File "C:\Users\adlerluc\AppData\Local\Programs\Python\Python312\Lib\asyncio\windows_events.py", line 462, in finish_socket_func
    return ov.getresult()
           ^^^^^^^^^^^^^^
OSError: [WinError 64] Der angegebene Netzwerkname ist nicht mehr verfügbar

During handling of the above exception, another exception occurred:

Traceback (most recent call last):
  File "C:\Users\adlerluc\Pictures\workspace2\.venv\Lib\site-packages\aiohttp\connector.py", line 1283, in _wrap_create_connection
    return await self._loop.create_connection(*args, **kwargs, sock=sock)
           ^^^^^^^^^^^^^^^^^^^^^^^^^^^^^^^^^^^^^^^^^^^^^^^^^^^^^^^^^^^^^^
  File "C:\Users\adlerluc\AppData\Local\Programs\Python\Python312\Lib\asyncio\base_events.py", line 1149, in create_connection
    transport, protocol = await self._create_connection_transport(
                          ^^^^^^^^^^^^^^^^^^^^^^^^^^^^^^^^^^^^^^^^
  File "C:\Users\adlerluc\AppData\Local\Programs\Python\Python312\Lib\asyncio\base_events.py", line 1182, in _create_connection_transport
    await waiter
  File "C:\Users\adlerluc\AppData\Local\Programs\Python\Python312\Lib\asyncio\proactor_events.py", line 286, in _loop_reading
    length = fut.result()
             ^^^^^^^^^^^^
  File "C:\Users\adlerluc\AppData\Local\Programs\Python\Python312\Lib\asyncio\windows_events.py", line 803, in _poll
    value = callback(transferred, key, ov)
            ^^^^^^^^^^^^^^^^^^^^^^^^^^^^^^
  File "C:\Users\adlerluc\AppData\Local\Programs\Python\Python312\Lib\asyncio\windows_events.py", line 466, in finish_socket_func
    raise ConnectionResetError(*exc.args)
ConnectionResetError: [WinError 64] Der angegebene Netzwerkname ist nicht mehr verfügbar

The above exception was the direct cause of the following exception:

Traceback (most recent call last):
  File "C:\Users\adlerluc\Pictures\workspace2\Bot.py", line 135, in ensure_token
    async with session.post(url, params=params) as resp:
  File "C:\Users\adlerluc\Pictures\workspace2\.venv\Lib\site-packages\aiohttp\client.py", line 1488, in __aenter__
    self._resp: _RetType = await self._coro
                           ^^^^^^^^^^^^^^^^
  File "C:\Users\adlerluc\Pictures\workspace2\.venv\Lib\site-packages\aiohttp\client.py", line 770, in _request
    resp = await handler(req)
           ^^^^^^^^^^^^^^^^^^
  File "C:\Users\adlerluc\Pictures\workspace2\.venv\Lib\site-packages\aiohttp\client.py", line 725, in _connect_and_send_request
    conn = await self._connector.connect(
           ^^^^^^^^^^^^^^^^^^^^^^^^^^^^^^
  File "C:\Users\adlerluc\Pictures\workspace2\.venv\Lib\site-packages\aiohttp\connector.py", line 642, in connect
    proto = await self._create_connection(req, traces, timeout)
            ^^^^^^^^^^^^^^^^^^^^^^^^^^^^^^^^^^^^^^^^^^^^^^^^^^^
  File "C:\Users\adlerluc\Pictures\workspace2\.venv\Lib\site-packages\aiohttp\connector.py", line 1209, in _create_connection
    _, proto = await self._create_direct_connection(req, traces, timeout)
               ^^^^^^^^^^^^^^^^^^^^^^^^^^^^^^^^^^^^^^^^^^^^^^^^^^^^^^^^^^
  File "C:\Users\adlerluc\Pictures\workspace2\.venv\Lib\site-packages\aiohttp\connector.py", line 1581, in _create_direct_connection
    raise last_exc
  File "C:\Users\adlerluc\Pictures\workspace2\.venv\Lib\site-packages\aiohttp\connector.py", line 1550, in _create_direct_connection
    transp, proto = await self._wrap_create_connection(
                    ^^^^^^^^^^^^^^^^^^^^^^^^^^^^^^^^^^^
  File "C:\Users\adlerluc\Pictures\workspace2\.venv\Lib\site-packages\aiohttp\connector.py", line 1291, in _wrap_create_connection
    raise client_error(req.connection_key, exc) from exc
aiohttp.client_exceptions.ClientConnectorError: Cannot connect to host id.twitch.tv:443 ssl:default [Der angegebene Netzwerkname ist nicht mehr verfügbar]
2025-08-18 08:39:38 ERROR: Fehler beim Prüfen von shurjoka in Guild 1405456407867822182: Cannot connect to host id.twitch.tv:443 ssl:default [Der angegebene Netzwerkname ist nicht mehr verfügbar]
Traceback (most recent call last):
  File "C:\Users\adlerluc\AppData\Local\Programs\Python\Python312\Lib\asyncio\windows_events.py", line 462, in finish_socket_func
    return ov.getresult()
           ^^^^^^^^^^^^^^
OSError: [WinError 64] Der angegebene Netzwerkname ist nicht mehr verfügbar

During handling of the above exception, another exception occurred:

Traceback (most recent call last):
  File "C:\Users\adlerluc\Pictures\workspace2\.venv\Lib\site-packages\aiohttp\connector.py", line 1283, in _wrap_create_connection
    return await self._loop.create_connection(*args, **kwargs, sock=sock)
           ^^^^^^^^^^^^^^^^^^^^^^^^^^^^^^^^^^^^^^^^^^^^^^^^^^^^^^^^^^^^^^
  File "C:\Users\adlerluc\AppData\Local\Programs\Python\Python312\Lib\asyncio\base_events.py", line 1149, in create_connection
    transport, protocol = await self._create_connection_transport(
                          ^^^^^^^^^^^^^^^^^^^^^^^^^^^^^^^^^^^^^^^^
  File "C:\Users\adlerluc\AppData\Local\Programs\Python\Python312\Lib\asyncio\base_events.py", line 1182, in _create_connection_transport
    await waiter
  File "C:\Users\adlerluc\AppData\Local\Programs\Python\Python312\Lib\asyncio\proactor_events.py", line 286, in _loop_reading
    length = fut.result()
             ^^^^^^^^^^^^
  File "C:\Users\adlerluc\AppData\Local\Programs\Python\Python312\Lib\asyncio\windows_events.py", line 803, in _poll
    value = callback(transferred, key, ov)
            ^^^^^^^^^^^^^^^^^^^^^^^^^^^^^^
  File "C:\Users\adlerluc\AppData\Local\Programs\Python\Python312\Lib\asyncio\windows_events.py", line 466, in finish_socket_func
    raise ConnectionResetError(*exc.args)
ConnectionResetError: [WinError 64] Der angegebene Netzwerkname ist nicht mehr verfügbar

The above exception was the direct cause of the following exception:

Traceback (most recent call last):
  File "C:\Users\adlerluc\Pictures\workspace2\Bot.py", line 214, in check_stream
    data = await twitch.get_stream(session, streamer)
           ^^^^^^^^^^^^^^^^^^^^^^^^^^^^^^^^^^^^^^^^^^
  File "C:\Users\adlerluc\Pictures\workspace2\Bot.py", line 153, in get_stream
    await self.ensure_token(session)
  File "C:\Users\adlerluc\Pictures\workspace2\Bot.py", line 135, in ensure_token
    async with session.post(url, params=params) as resp:
  File "C:\Users\adlerluc\Pictures\workspace2\.venv\Lib\site-packages\aiohttp\client.py", line 1488, in __aenter__
    self._resp: _RetType = await self._coro
                           ^^^^^^^^^^^^^^^^
  File "C:\Users\adlerluc\Pictures\workspace2\.venv\Lib\site-packages\aiohttp\client.py", line 770, in _request
    resp = await handler(req)
           ^^^^^^^^^^^^^^^^^^
  File "C:\Users\adlerluc\Pictures\workspace2\.venv\Lib\site-packages\aiohttp\client.py", line 725, in _connect_and_send_request
    conn = await self._connector.connect(
           ^^^^^^^^^^^^^^^^^^^^^^^^^^^^^^
  File "C:\Users\adlerluc\Pictures\workspace2\.venv\Lib\site-packages\aiohttp\connector.py", line 642, in connect
    proto = await self._create_connection(req, traces, timeout)
            ^^^^^^^^^^^^^^^^^^^^^^^^^^^^^^^^^^^^^^^^^^^^^^^^^^^
  File "C:\Users\adlerluc\Pictures\workspace2\.venv\Lib\site-packages\aiohttp\connector.py", line 1209, in _create_connection
    _, proto = await self._create_direct_connection(req, traces, timeout)
               ^^^^^^^^^^^^^^^^^^^^^^^^^^^^^^^^^^^^^^^^^^^^^^^^^^^^^^^^^^
  File "C:\Users\adlerluc\Pictures\workspace2\.venv\Lib\site-packages\aiohttp\connector.py", line 1581, in _create_direct_connection
    raise last_exc
  File "C:\Users\adlerluc\Pictures\workspace2\.venv\Lib\site-packages\aiohttp\connector.py", line 1550, in _create_direct_connection
    transp, proto = await self._wrap_create_connection(
                    ^^^^^^^^^^^^^^^^^^^^^^^^^^^^^^^^^^^
  File "C:\Users\adlerluc\Pictures\workspace2\.venv\Lib\site-packages\aiohttp\connector.py", line 1291, in _wrap_create_connection
    raise client_error(req.connection_key, exc) from exc
aiohttp.client_exceptions.ClientConnectorError: Cannot connect to host id.twitch.tv:443 ssl:default [Der angegebene Netzwerkname ist nicht mehr verfügbar]
2025-08-18 08:39:47 ERROR: Unclosed client session
client_session: <aiohttp.client.ClientSession object at 0x00000252FA9D22A0>
